---
timestamp: 'Wed Oct 15 2025 19:26:00 GMT-0400 (Eastern Daylight Time)'
parent: '[[../20251015_192600.b602ca9d.md]]'
content_id: b83290f6d55106b3ef4ba85bb5d9f8c7dfcd8a3d6aaef2d62081d6106d940e22
---

# response:

You're encountering this TypeScript error because the return type of `concept._getCurrentItem` is a union type: `_GetCurrentItemSuccess | _GetCurrentItemError`.

The `_GetCurrentItemSuccess` type likely looks something like `{ index: number; }`, while `_GetCurrentItemError` would be `{ error: string; }`. TypeScript sees that `currentStatus` *could* be the error type, which doesn't have an `index` property, and therefore flags it as a potential error.

To fix this, you need to add a type guard to ensure that `currentStatus` is the successful return type before trying to access `index`.

Here's how you can modify the problematic `t.step` block:

```typescript
Deno.test("Action: next, back, jumpTo", async (t) => {
  const [db, client] = await testDb();
  const config = await loadConfig();
  const llm = new GeminiLLM(config);
  const concept = new FileTrackerConcept(db, llm);

  // ... (previous steps)

  await t.step(
    "5. User cannot jump to an invalid index (negative, out of bounds, non-integer)",
    async () => {
      // Current index is file1MaxIndex from previous step
      const initialStatusResult = await concept._getCurrentItem({
        owner: userAlice,
        file: file1,
      });

      // Type guard: Ensure initialStatusResult is not an error before accessing index
      if ("error" in initialStatusResult) {
        throw new Error(
          `Expected a successful status, but got an error: ${initialStatusResult.error}`,
        );
      }
      const originalIndex = initialStatusResult.index; // Now TypeScript knows initialStatusResult has 'index'

      // Test negative index
      let jumpResult = await concept.jumpTo({
        owner: userAlice,
        file: file1,
        index: -1,
      });
      assertEquals(
        "error" in jumpResult,
        true,
        "Jumping to a negative index should fail.",
      );
      assertEquals(
        (jumpResult as { error: string }).error,
        `Index '-1' is out of bounds [0, ${file1MaxIndex}] or not an integer.`,
        "Error message should indicate out of bounds for negative index.",
      );
      let statusResult = await concept._getCurrentItem({
        owner: userAlice,
        file: file1,
      });
      if ("error" in statusResult) {
        throw new Error(
          `Expected a successful status, but got an error: ${statusResult.error}`,
        );
      }
      assertEquals(
        statusResult.index, // Now TypeScript knows statusResult has 'index'
        originalIndex,
        "Index should not change for invalid jump.",
      );

      // Test index greater than maxIndex
      jumpResult = await concept.jumpTo({
        owner: userAlice,
        file: file1,
        index: file1MaxIndex + 1,
      });
      assertEquals(
        "error" in jumpResult,
        true,
        "Jumping to an index > maxIndex should fail.",
      );
      assertEquals(
        (jumpResult as { error: string }).error,
        `Index '${
          file1MaxIndex + 1
        }' is out of bounds [0, ${file1MaxIndex}] or not an integer.`,
        "Error message should indicate out of bounds for index > maxIndex.",
      );
      statusResult = await concept._getCurrentItem({
        owner: userAlice,
        file: file1,
      });
      if ("error" in statusResult) {
        throw new Error(
          `Expected a successful status, but got an error: ${statusResult.error}`,
        );
      }
      assertEquals(
        statusResult.index,
        originalIndex,
        "Index should not change for invalid jump.",
      );

      // Test non-integer index
      jumpResult = await concept.jumpTo({
        owner: userAlice,
        file: file1,
        index: 3.5,
      });
      assertEquals(
        "error" in jumpResult,
        true,
        "Jumping to a non-integer index should fail.",
      );
      assertEquals(
        (jumpResult as { error: string }).error,
        `Index '3.5' is out of bounds [0, ${file1MaxIndex}] or not an integer.`,
        "Error message should indicate non-integer index.",
      );
      statusResult = await concept._getCurrentItem({
        owner: userAlice,
        file: file1,
      });
      if ("error" in statusResult) {
        throw new Error(
          `Expected a successful status, but got an error: ${statusResult.error}`,
        );
      }
      assertEquals(
        statusResult.index,
        originalIndex,
        "Index should not change for invalid jump.",
      );
    },
  );
  await client.close();
});
```

**Explanation:**

1. **`initialStatusResult` and `statusResult`:** I've renamed `currentStatus` to `initialStatusResult` (and later `statusResult`) to emphasize that it's the *result* of the operation, which could be either success or error.
2. **Type Guard `if ("error" in initialStatusResult)`:** This is the key. Before accessing `initialStatusResult.index`, we check if the `error` property exists in `initialStatusResult`.
   * If `true`, TypeScript understands that `initialStatusResult` is of type `{ error: string; }`. In a test where you *expect* a successful retrieval, you'd typically `throw new Error()` or `assertNotEquals("error" in initialStatusResult, true)` to fail the test.
   * If `false` (meaning the `error` property does *not* exist), TypeScript automatically narrows the type of `initialStatusResult` within that `if` block's `else` branch (or after the `if` block if you throw an error) to `{ index: number; }`. This allows you to safely access `initialStatusResult.index`.

This approach makes your code type-safe and handles the possibility of an error response from `_getCurrentItem`, even if you expect success in that particular test context.
